<?xml version="1.0"?>
<robot xmlns:xacro="http://www.ros.org/wiki/xacro" name="two_wheel_bike">

  <!-- Constants for realistic motorcycle -->
  <xacro:property name="PI" value="3.1415926535897931"/>
  <xacro:property name="chassis_mass" value="120.0"/>  <!-- Heavier like real motorcycle -->
  <xacro:property name="wheel_mass" value="8.0"/>     <!-- Heavier wheels for gyroscopic effect -->
  <xacro:property name="fork_mass" value="5.0"/>
  <xacro:property name="wheel_radius" value="0.35"/>   <!-- Larger wheels -->
  <xacro:property name="wheel_width" value="0.15"/>    <!-- Wider tires -->
  <xacro:property name="chassis_length" value="1.8"/>  <!-- Longer wheelbase -->
  <xacro:property name="chassis_height" value="0.5"/>
  <xacro:property name="chassis_width" value="0.2"/>
  <xacro:property name="fork_length" value="0.7"/>     <!-- Longer fork -->
  <xacro:property name="caster_angle" value="${PI/9}"/> <!-- 20 degrees caster -->

  <!-- Base Link (Main Frame) -->
  <link name="base_link">
    <visual>
      <origin xyz="0 0 ${wheel_radius + chassis_height/2}" rpy="0 0 0"/>
      <geometry>
        <box size="${chassis_length} ${chassis_width} ${chassis_height}"/>
      </geometry>
      <material name="red">
        <color rgba="0.8 0.2 0.2 1.0"/>
      </material>
    </visual>
    <collision>
      <origin xyz="0 0 ${wheel_radius + chassis_height/2}" rpy="0 0 0"/>
      <geometry>
        <box size="${chassis_length} ${chassis_width} ${chassis_height}"/>
      </geometry>
    </collision>
    <inertial>
      <origin xyz="0 0 ${chassis_height/2}" rpy="0 0 0"/>
      <mass value="${chassis_mass}"/>
      <inertia ixx="${chassis_mass*(chassis_width*chassis_width+chassis_height*chassis_height)/12}" 
               ixy="0" ixz="0" 
               iyy="${chassis_mass*(chassis_length*chassis_length+chassis_height*chassis_height)/12}" 
               iyz="0" 
               izz="${chassis_mass*(chassis_length*chassis_length+chassis_width*chassis_width)/12}"/>
    </inertial>
  </link>

  <!-- Rear Wheel with high rotational inertia for gyroscopic effect -->
  <link name="rear_wheel_link">
    <visual>
      <origin xyz="0 0 0" rpy="${PI/2} 0 0"/>
      <geometry>
        <cylinder radius="${wheel_radius}" length="${wheel_width}"/>
      </geometry>
      <material name="black">
        <color rgba="0.1 0.1 0.1 1.0"/>
      </material>
    </visual>
    <collision>
      <origin xyz="0 0 0" rpy="${PI/2} 0 0"/>
      <geometry>
        <cylinder radius="${wheel_radius}" length="${wheel_width}"/>
      </geometry>
      <surface>
        <friction>
          <ode>
            <mu>1.5</mu>    <!-- High friction for traction -->
            <mu2>1.5</mu2>
          </ode>
        </friction>
      </surface>
    </collision>
    <inertial>
      <origin xyz="0 0 0" rpy="0 0 0"/>
      <mass value="${wheel_mass}"/>
      <!-- High rotational inertia for gyroscopic stability -->
      <inertia ixx="${wheel_mass*(3*wheel_radius*wheel_radius+wheel_width*wheel_width)/12}" 
               ixy="0" ixz="0" 
               iyy="${wheel_mass*(3*wheel_radius*wheel_radius+wheel_width*wheel_width)/12}" 
               iyz="0" 
               izz="${wheel_mass*wheel_radius*wheel_radius}"/>  <!-- Increased for gyroscopic effect -->
    </inertial>
  </link>

  <joint name="rear_wheel_joint" type="continuous">
    <parent link="base_link"/>
    <child link="rear_wheel_link"/>
    <origin xyz="-${chassis_length/2 - 0.2} 0 ${wheel_radius}" rpy="0 0 0"/>
    <axis xyz="0 1 0"/>
    <dynamics damping="0.5" friction="0.1"/>  <!-- Some damping for realism -->
  </joint>

  <!-- Front Fork with proper caster angle -->
  <link name="front_fork_link">
    <visual>
        <origin xyz="${fork_length*sin(caster_angle)/2} 0 -${fork_length*cos(caster_angle)/2}" 
                rpy="0 ${caster_angle} 0"/>
        <geometry>
            <box size="0.08 0.08 ${fork_length}"/>
        </geometry>
        <material name="silver">
            <color rgba="0.7 0.7 0.7 1.0"/>
        </material>
    </visual>
    <collision>
        <origin xyz="${fork_length*sin(caster_angle)/2} 0 -${fork_length*cos(caster_angle)/2}" 
                rpy="0 ${caster_angle} 0"/>
        <geometry>
            <box size="0.08 0.08 ${fork_length}"/>
        </geometry>
    </collision>
    <inertial>
      <origin xyz="0 0 0" rpy="0 0 0"/>
      <mass value="${fork_mass}"/>
      <inertia ixx="${fork_mass*(0.08*0.08+fork_length*fork_length)/12}" 
               ixy="0" ixz="0" 
               iyy="${fork_mass*(0.08*0.08+fork_length*fork_length)/12}" 
               iyz="0" 
               izz="${fork_mass*(0.08*0.08+0.08*0.08)/12}"/>
    </inertial>
  </link>

  <joint name="steering_joint" type="revolute">
    <parent link="base_link"/>
    <child link="front_fork_link"/>
    <origin xyz="${chassis_length/2 - 0.2} 0 ${wheel_radius + chassis_height/2}" rpy="0 0 0"/>
    <axis xyz="0 0 1"/>
    <limit lower="-0.698" upper="0.698" effort="50" velocity="2"/>  <!-- ±40 degrees, higher torque -->
    <dynamics damping="1.0" friction="0.2"/>
  </joint>

  <!-- Front Wheel with gyroscopic properties -->
  <link name="front_wheel_link">
    <visual>
      <origin xyz="0 0 0" rpy="${PI/2} 0 0"/>
      <geometry>
        <cylinder radius="${wheel_radius}" length="${wheel_width}"/>
      </geometry>
      <material name="black">
        <color rgba="0.1 0.1 0.1 1.0"/>
      </material>
    </visual>
    <collision>
      <origin xyz="0 0 0" rpy="${PI/2} 0 0"/>
      <geometry>
        <cylinder radius="${wheel_radius}" length="${wheel_width}"/>
      </geometry>
      <surface>
        <friction>
          <ode>
            <mu>1.5</mu>
            <mu2>1.2</mu2>  <!-- Slightly less lateral friction for steering -->
          </ode>
        </friction>
      </surface>
    </collision>
    <inertial>
      <origin xyz="0 0 0" rpy="0 0 0"/>
      <mass value="${wheel_mass}"/>
      <inertia ixx="${wheel_mass*(3*wheel_radius*wheel_radius+wheel_width*wheel_width)/12}" 
               ixy="0" ixz="0" 
               iyy="${wheel_mass*(3*wheel_radius*wheel_radius+wheel_width*wheel_width)/12}" 
               iyz="0" 
               izz="${wheel_mass*wheel_radius*wheel_radius}"/>  <!-- High rotational inertia -->
    </inertial>
  </link>

  <joint name="front_wheel_joint" type="continuous">
    <parent link="front_fork_link"/>
    <child link="front_wheel_link"/>
    <origin xyz="${fork_length*sin(caster_angle)} 0 -${fork_length*cos(caster_angle)}" 
            rpy="0 ${caster_angle} 0"/>
    <axis xyz="0 1 0"/>
    <dynamics damping="0.5" friction="0.1"/>
  </joint>

  <!-- Gazebo materials -->
  <gazebo reference="base_link">
    <material>Gazebo/Red</material>
    <mu1>0.3</mu1>
    <mu2>0.3</mu2>
  </gazebo>

  <gazebo reference="rear_wheel_link">
    <material>Gazebo/Black</material>
    <mu1>1.8</mu1>  <!-- High traction -->
    <mu2>1.5</mu2>
    <kp>10000000</kp>
    <kd>1000</kd>
  </gazebo>

  <gazebo reference="front_wheel_link">
    <material>Gazebo/Black</material>
    <mu1>1.5</mu1>
    <mu2>1.2</mu2>  <!-- Allow some slip for steering -->
    <kp>10000000</kp>
    <kd>1000</kd>
  </gazebo>

  <gazebo reference="front_fork_link">
    <material>Gazebo/Grey</material>
  </gazebo>

  <!-- IMU on the main frame -->
  <gazebo reference="base_link">
    <sensor name="imu_sensor" type="imu">
      <always_on>true</always_on>
      <update_rate>100</update_rate>
      <plugin filename="libgazebo_ros_imu_sensor.so" name="imu_plugin">
        <topicName>imu</topicName>
        <bodyName>base_link</bodyName>
        <updateRateHZ>100.0</updateRateHZ>
        <gaussianNoise>0.01</gaussianNoise>
        <xyzOffset>0 0 0</xyzOffset>
        <rpyOffset>0 0 0</rpyOffset>
        <frameName>base_link</frameName>
        <initialOrientationAsReference>false</initialOrientationAsReference>
      </plugin>
    </sensor>
  </gazebo>

  <!-- Custom motorcycle controller plugin -->
  <gazebo>
    <plugin name="motorcycle_controller" filename="libgazebo_ros_diff_drive.so">
        <robotNamespace>/</robotNamespace>
        
        <!-- Use rear wheel for drive, steering for direction -->
        <leftJoint>rear_wheel_joint</leftJoint>
        <rightJoint>rear_wheel_joint</rightJoint>  <!-- Same wheel for both to avoid differential -->

        <wheelSeparation>0.1</wheelSeparation>  <!-- Small separation since both are same wheel -->
        <wheelDiameter>${2*wheel_radius}</wheelDiameter>
        
        <maxWheelTorque>200</maxWheelTorque>  <!-- High torque for acceleration -->
        <maxWheelAcceleration>5.0</maxWheelAcceleration>

        <commandTopic>cmd_vel</commandTopic>
        <odometryTopic>odom</odometryTopic>
        <odometryFrame>odom</odometryFrame>
        <robotBaseFrame>base_link</robotBaseFrame>

        <publishOdom>true</publishOdom>
        <publishOdomTF>true</publishOdomTF>
        <publishWheelTF>false</publishWheelTF>

        <updateRate>50</updateRate>  <!-- Higher update rate -->
        <legacyMode>false</legacyMode>
    </plugin>
  </gazebo>

  <!-- Separate steering controller -->
  <gazebo>
    <plugin name="steering_controller" filename="libgazebo_ros_joint_state_publisher.so">
      <robotNamespace>/</robotNamespace>
      <jointName>steering_joint</jointName>
      <updateRate>50</updateRate>
    </plugin>
  </gazebo>

  <!-- Physics properties for realistic simulation -->
  <gazebo>
    <plugin name="gazebo_ros_control" filename="libgazebo_ros_control.so">
      <robotNamespace>/</robotNamespace>
    </plugin>
  </gazebo>

</robot>